[2022-08-22 20:34:55,465] {{taskinstance.py:655}} INFO - Dependencies all met for <TaskInstance: hello_postgres_postgres_operator.create_table 2022-08-22T20:34:37.941698+00:00 [queued]>
[2022-08-22 20:34:55,471] {{taskinstance.py:655}} INFO - Dependencies all met for <TaskInstance: hello_postgres_postgres_operator.create_table 2022-08-22T20:34:37.941698+00:00 [queued]>
[2022-08-22 20:34:55,472] {{taskinstance.py:866}} INFO - 
--------------------------------------------------------------------------------
[2022-08-22 20:34:55,472] {{taskinstance.py:867}} INFO - Starting attempt 1 of 1
[2022-08-22 20:34:55,473] {{taskinstance.py:868}} INFO - 
--------------------------------------------------------------------------------
[2022-08-22 20:34:55,483] {{taskinstance.py:887}} INFO - Executing <Task(PostgresOperator): create_table> on 2022-08-22T20:34:37.941698+00:00
[2022-08-22 20:34:55,486] {{standard_task_runner.py:53}} INFO - Started process 2813 to run task
[2022-08-22 20:34:55,522] {{logging_mixin.py:112}} INFO - Running %s on host %s <TaskInstance: hello_postgres_postgres_operator.create_table 2022-08-22T20:34:37.941698+00:00 [running]> myairflow
[2022-08-22 20:34:55,529] {{postgres_operator.py:62}} INFO - Executing: 
           CREATE TABLE testing_connection (
                dummy_column INTEGER NOT NULL PRIMARY KEY
            );
           
          
[2022-08-22 20:34:55,532] {{logging_mixin.py:112}} INFO - [2022-08-22 20:34:55,532] {{base_hook.py:84}} INFO - Using connection to: id: mypostgres_connection. Host: mypostgres, Port: 5432, Schema: postgres, Login: postgres, Password: None, extra: None
[2022-08-22 20:34:55,535] {{taskinstance.py:1128}} ERROR - fe_sendauth: no password supplied
Traceback (most recent call last):
  File "/usr/local/lib/python3.7/site-packages/airflow/models/taskinstance.py", line 966, in _run_raw_task
    result = task_copy.execute(context=context)
  File "/usr/local/lib/python3.7/site-packages/airflow/operators/postgres_operator.py", line 65, in execute
    self.hook.run(self.sql, self.autocommit, parameters=self.parameters)
  File "/usr/local/lib/python3.7/site-packages/airflow/hooks/dbapi_hook.py", line 162, in run
    with closing(self.get_conn()) as conn:
  File "/usr/local/lib/python3.7/site-packages/airflow/hooks/postgres_hook.py", line 93, in get_conn
    self.conn = psycopg2.connect(**conn_args)
  File "/usr/local/lib/python3.7/site-packages/psycopg2/__init__.py", line 126, in connect
    conn = _connect(dsn, connection_factory=connection_factory, **kwasync)
psycopg2.OperationalError: fe_sendauth: no password supplied

[2022-08-22 20:34:55,537] {{taskinstance.py:1185}} INFO - Marking task as FAILED.dag_id=hello_postgres_postgres_operator, task_id=create_table, execution_date=20220822T203437, start_date=20220822T203455, end_date=20220822T203455
[2022-08-22 20:35:05,382] {{logging_mixin.py:112}} INFO - [2022-08-22 20:35:05,382] {{local_task_job.py:103}} INFO - Task exited with return code 1
